[2022-02-01 08:58:52,651] {taskinstance.py:1032} INFO - Dependencies all met for <TaskInstance: gcp_ingest_yellow_taxi.format_to_parquet_task scheduled__2019-01-02T05:00:00+00:00 [queued]>
[2022-02-01 08:58:52,662] {taskinstance.py:1032} INFO - Dependencies all met for <TaskInstance: gcp_ingest_yellow_taxi.format_to_parquet_task scheduled__2019-01-02T05:00:00+00:00 [queued]>
[2022-02-01 08:58:52,662] {taskinstance.py:1238} INFO - 
--------------------------------------------------------------------------------
[2022-02-01 08:58:52,663] {taskinstance.py:1239} INFO - Starting attempt 1 of 1
[2022-02-01 08:58:52,663] {taskinstance.py:1240} INFO - 
--------------------------------------------------------------------------------
[2022-02-01 08:58:52,678] {taskinstance.py:1259} INFO - Executing <Task(PythonOperator): format_to_parquet_task> on 2019-01-02 05:00:00+00:00
[2022-02-01 08:58:52,687] {standard_task_runner.py:52} INFO - Started process 5364 to run task
[2022-02-01 08:58:52,697] {standard_task_runner.py:76} INFO - Running: ['***', 'tasks', 'run', 'gcp_ingest_yellow_taxi', 'format_to_parquet_task', 'scheduled__2019-01-02T05:00:00+00:00', '--job-id', '549', '--raw', '--subdir', 'DAGS_FOLDER/dag_***_gcp_yellow_taxi.py', '--cfg-path', '/tmp/tmptc01hbtp', '--error-file', '/tmp/tmp_j_sp92x']
[2022-02-01 08:58:52,699] {standard_task_runner.py:77} INFO - Job 549: Subtask format_to_parquet_task
[2022-02-01 08:58:52,782] {logging_mixin.py:109} INFO - Running <TaskInstance: gcp_ingest_yellow_taxi.format_to_parquet_task scheduled__2019-01-02T05:00:00+00:00 [running]> on host 78d49910abc7
[2022-02-01 08:58:52,834] {logging_mixin.py:109} WARNING - /home/***/.local/lib/python3.7/site-packages/***/utils/context.py:152 AirflowContextDeprecationWarning: Accessing 'execution_date' from the template is deprecated and will be removed in a future version. Please use 'data_interval_start' or 'logical_date' instead.
[2022-02-01 08:58:52,860] {taskinstance.py:1426} INFO - Exporting the following env vars:
AIRFLOW_CTX_DAG_OWNER=***
AIRFLOW_CTX_DAG_ID=gcp_ingest_yellow_taxi
AIRFLOW_CTX_TASK_ID=format_to_parquet_task
AIRFLOW_CTX_EXECUTION_DATE=2019-01-02T05:00:00+00:00
AIRFLOW_CTX_DAG_RUN_ID=scheduled__2019-01-02T05:00:00+00:00
[2022-02-01 08:58:52,871] {taskinstance.py:1700} ERROR - Task failed with exception
Traceback (most recent call last):
  File "/home/airflow/.local/lib/python3.7/site-packages/airflow/models/taskinstance.py", line 1329, in _run_raw_task
    self._execute_task_with_callbacks(context)
  File "/home/airflow/.local/lib/python3.7/site-packages/airflow/models/taskinstance.py", line 1455, in _execute_task_with_callbacks
    result = self._execute_task(context, self.task)
  File "/home/airflow/.local/lib/python3.7/site-packages/airflow/models/taskinstance.py", line 1511, in _execute_task
    result = execute_callable(context=context)
  File "/home/airflow/.local/lib/python3.7/site-packages/airflow/operators/python.py", line 174, in execute
    return_value = self.execute_callable()
  File "/home/airflow/.local/lib/python3.7/site-packages/airflow/operators/python.py", line 185, in execute_callable
    return self.python_callable(*self.op_args, **self.op_kwargs)
  File "/opt/airflow/dags/dag_airflow_gcp_yellow_taxi.py", line 36, in format_to_parquet
    table = pv.read_csv(src_file)
  File "pyarrow/_csv.pyx", line 862, in pyarrow._csv.read_csv
  File "pyarrow/_csv.pyx", line 755, in pyarrow._csv._get_reader
  File "pyarrow/io.pxi", line 1551, in pyarrow.lib.get_input_stream
  File "pyarrow/io.pxi", line 1522, in pyarrow.lib.get_native_file
  File "pyarrow/io.pxi", line 886, in pyarrow.lib.OSFile.__cinit__
  File "pyarrow/io.pxi", line 896, in pyarrow.lib.OSFile._open_readable
  File "pyarrow/error.pxi", line 143, in pyarrow.lib.pyarrow_internal_check_status
  File "pyarrow/error.pxi", line 112, in pyarrow.lib.check_status
FileNotFoundError: [Errno 2] Failed to open local file '/opt/airflow/yellow_taxi_output_2019-01.csv'. Detail: [errno 2] No such file or directory
[2022-02-01 08:58:52,894] {taskinstance.py:1277} INFO - Marking task as FAILED. dag_id=gcp_ingest_yellow_taxi, task_id=format_to_parquet_task, execution_date=20190102T050000, start_date=20220201T085852, end_date=20220201T085852
[2022-02-01 08:58:52,909] {standard_task_runner.py:92} ERROR - Failed to execute job 549 for task format_to_parquet_task
Traceback (most recent call last):
  File "/home/airflow/.local/lib/python3.7/site-packages/airflow/task/task_runner/standard_task_runner.py", line 85, in _start_by_fork
    args.func(args, dag=self.dag)
  File "/home/airflow/.local/lib/python3.7/site-packages/airflow/cli/cli_parser.py", line 48, in command
    return func(*args, **kwargs)
  File "/home/airflow/.local/lib/python3.7/site-packages/airflow/utils/cli.py", line 92, in wrapper
    return f(*args, **kwargs)
  File "/home/airflow/.local/lib/python3.7/site-packages/airflow/cli/commands/task_command.py", line 298, in task_run
    _run_task_by_selected_method(args, dag, ti)
  File "/home/airflow/.local/lib/python3.7/site-packages/airflow/cli/commands/task_command.py", line 107, in _run_task_by_selected_method
    _run_raw_task(args, ti)
  File "/home/airflow/.local/lib/python3.7/site-packages/airflow/cli/commands/task_command.py", line 184, in _run_raw_task
    error_file=args.error_file,
  File "/home/airflow/.local/lib/python3.7/site-packages/airflow/utils/session.py", line 70, in wrapper
    return func(*args, session=session, **kwargs)
  File "/home/airflow/.local/lib/python3.7/site-packages/airflow/models/taskinstance.py", line 1329, in _run_raw_task
    self._execute_task_with_callbacks(context)
  File "/home/airflow/.local/lib/python3.7/site-packages/airflow/models/taskinstance.py", line 1455, in _execute_task_with_callbacks
    result = self._execute_task(context, self.task)
  File "/home/airflow/.local/lib/python3.7/site-packages/airflow/models/taskinstance.py", line 1511, in _execute_task
    result = execute_callable(context=context)
  File "/home/airflow/.local/lib/python3.7/site-packages/airflow/operators/python.py", line 174, in execute
    return_value = self.execute_callable()
  File "/home/airflow/.local/lib/python3.7/site-packages/airflow/operators/python.py", line 185, in execute_callable
    return self.python_callable(*self.op_args, **self.op_kwargs)
  File "/opt/airflow/dags/dag_airflow_gcp_yellow_taxi.py", line 36, in format_to_parquet
    table = pv.read_csv(src_file)
  File "pyarrow/_csv.pyx", line 862, in pyarrow._csv.read_csv
  File "pyarrow/_csv.pyx", line 755, in pyarrow._csv._get_reader
  File "pyarrow/io.pxi", line 1551, in pyarrow.lib.get_input_stream
  File "pyarrow/io.pxi", line 1522, in pyarrow.lib.get_native_file
  File "pyarrow/io.pxi", line 886, in pyarrow.lib.OSFile.__cinit__
  File "pyarrow/io.pxi", line 896, in pyarrow.lib.OSFile._open_readable
  File "pyarrow/error.pxi", line 143, in pyarrow.lib.pyarrow_internal_check_status
  File "pyarrow/error.pxi", line 112, in pyarrow.lib.check_status
FileNotFoundError: [Errno 2] Failed to open local file '/opt/airflow/yellow_taxi_output_2019-01.csv'. Detail: [errno 2] No such file or directory
[2022-02-01 08:58:52,947] {local_task_job.py:154} INFO - Task exited with return code 1
[2022-02-01 08:58:52,988] {local_task_job.py:264} INFO - 0 downstream tasks scheduled from follow-on schedule check
