[2022-02-01 07:37:57,215] {taskinstance.py:1032} INFO - Dependencies all met for <TaskInstance: data_ingestion_gcs_dag.download_dataset_task scheduled__2022-01-31T00:00:00+00:00 [queued]>
[2022-02-01 07:37:57,237] {taskinstance.py:1032} INFO - Dependencies all met for <TaskInstance: data_ingestion_gcs_dag.download_dataset_task scheduled__2022-01-31T00:00:00+00:00 [queued]>
[2022-02-01 07:37:57,238] {taskinstance.py:1238} INFO - 
--------------------------------------------------------------------------------
[2022-02-01 07:37:57,239] {taskinstance.py:1239} INFO - Starting attempt 1 of 2
[2022-02-01 07:37:57,240] {taskinstance.py:1240} INFO - 
--------------------------------------------------------------------------------
[2022-02-01 07:37:57,259] {taskinstance.py:1259} INFO - Executing <Task(BashOperator): download_dataset_task> on 2022-01-31 00:00:00+00:00
[2022-02-01 07:37:57,270] {standard_task_runner.py:52} INFO - Started process 189 to run task
[2022-02-01 07:37:57,278] {standard_task_runner.py:76} INFO - Running: ['***', 'tasks', 'run', 'data_ingestion_gcs_dag', 'download_dataset_task', 'scheduled__2022-01-31T00:00:00+00:00', '--job-id', '541', '--raw', '--subdir', 'DAGS_FOLDER/data_ingestion_gcs_dag.py', '--cfg-path', '/tmp/tmp09dd5swj', '--error-file', '/tmp/tmpvg323x79']
[2022-02-01 07:37:57,282] {standard_task_runner.py:77} INFO - Job 541: Subtask download_dataset_task
[2022-02-01 07:37:57,390] {logging_mixin.py:109} INFO - Running <TaskInstance: data_ingestion_gcs_dag.download_dataset_task scheduled__2022-01-31T00:00:00+00:00 [running]> on host ddcb0d68d984
[2022-02-01 07:37:57,598] {taskinstance.py:1426} INFO - Exporting the following env vars:
AIRFLOW_CTX_DAG_OWNER=***
AIRFLOW_CTX_DAG_ID=data_ingestion_gcs_dag
AIRFLOW_CTX_TASK_ID=download_dataset_task
AIRFLOW_CTX_EXECUTION_DATE=2022-01-31T00:00:00+00:00
AIRFLOW_CTX_DAG_RUN_ID=scheduled__2022-01-31T00:00:00+00:00
[2022-02-01 07:37:57,601] {subprocess.py:62} INFO - Tmp dir root location: 
 /tmp
[2022-02-01 07:37:57,604] {subprocess.py:74} INFO - Running command: ['bash', '-c', 'curl -sS https://s3.amazonaws.com/nyc-tlc/trip+data/yellow_tripdata_2021-01.csv > /opt/***/yellow_tripdata_2021-01.csv']
[2022-02-01 07:37:57,650] {subprocess.py:85} INFO - Output:
[2022-02-01 07:39:20,365] {local_task_job.py:82} ERROR - Received SIGTERM. Terminating subprocesses
[2022-02-01 07:39:21,128] {process_utils.py:124} INFO - Sending Signals.SIGTERM to group 189. PIDs of all processes in the group: [190, 191, 189]
[2022-02-01 07:39:21,267] {process_utils.py:75} INFO - Sending the signal Signals.SIGTERM to group 189
[2022-02-01 07:39:21,410] {taskinstance.py:1408} ERROR - Received SIGTERM. Terminating subprocesses.
[2022-02-01 07:39:21,517] {subprocess.py:99} INFO - Sending SIGTERM signal to process group
[2022-02-01 07:39:21,599] {process_utils.py:70} INFO - Process psutil.Process(pid=191, status='terminated', started='07:37:57') (191) terminated with exit code None
[2022-02-01 07:39:21,648] {taskinstance.py:1700} ERROR - Task failed with exception
Traceback (most recent call last):
  File "/home/airflow/.local/lib/python3.7/site-packages/airflow/models/taskinstance.py", line 1329, in _run_raw_task
    self._execute_task_with_callbacks(context)
  File "/home/airflow/.local/lib/python3.7/site-packages/airflow/models/taskinstance.py", line 1455, in _execute_task_with_callbacks
    result = self._execute_task(context, self.task)
  File "/home/airflow/.local/lib/python3.7/site-packages/airflow/models/taskinstance.py", line 1511, in _execute_task
    result = execute_callable(context=context)
  File "/home/airflow/.local/lib/python3.7/site-packages/airflow/operators/bash.py", line 182, in execute
    cwd=self.cwd,
  File "/home/airflow/.local/lib/python3.7/site-packages/airflow/hooks/subprocess.py", line 87, in run_command
    for raw_line in iter(self.sub_process.stdout.readline, b''):
  File "/home/airflow/.local/lib/python3.7/site-packages/airflow/models/taskinstance.py", line 1410, in signal_handler
    raise AirflowException("Task received SIGTERM signal")
airflow.exceptions.AirflowException: Task received SIGTERM signal
[2022-02-01 07:39:21,676] {taskinstance.py:1277} INFO - Marking task as UP_FOR_RETRY. dag_id=data_ingestion_gcs_dag, task_id=download_dataset_task, execution_date=20220131T000000, start_date=20220201T073757, end_date=20220201T073921
[2022-02-01 07:39:21,730] {standard_task_runner.py:92} ERROR - Failed to execute job 541 for task download_dataset_task
Traceback (most recent call last):
  File "/home/airflow/.local/lib/python3.7/site-packages/airflow/task/task_runner/standard_task_runner.py", line 85, in _start_by_fork
    args.func(args, dag=self.dag)
  File "/home/airflow/.local/lib/python3.7/site-packages/airflow/cli/cli_parser.py", line 48, in command
    return func(*args, **kwargs)
  File "/home/airflow/.local/lib/python3.7/site-packages/airflow/utils/cli.py", line 92, in wrapper
    return f(*args, **kwargs)
  File "/home/airflow/.local/lib/python3.7/site-packages/airflow/cli/commands/task_command.py", line 298, in task_run
    _run_task_by_selected_method(args, dag, ti)
  File "/home/airflow/.local/lib/python3.7/site-packages/airflow/cli/commands/task_command.py", line 107, in _run_task_by_selected_method
    _run_raw_task(args, ti)
  File "/home/airflow/.local/lib/python3.7/site-packages/airflow/cli/commands/task_command.py", line 184, in _run_raw_task
    error_file=args.error_file,
  File "/home/airflow/.local/lib/python3.7/site-packages/airflow/utils/session.py", line 70, in wrapper
    return func(*args, session=session, **kwargs)
  File "/home/airflow/.local/lib/python3.7/site-packages/airflow/models/taskinstance.py", line 1329, in _run_raw_task
    self._execute_task_with_callbacks(context)
  File "/home/airflow/.local/lib/python3.7/site-packages/airflow/models/taskinstance.py", line 1455, in _execute_task_with_callbacks
    result = self._execute_task(context, self.task)
  File "/home/airflow/.local/lib/python3.7/site-packages/airflow/models/taskinstance.py", line 1511, in _execute_task
    result = execute_callable(context=context)
  File "/home/airflow/.local/lib/python3.7/site-packages/airflow/operators/bash.py", line 182, in execute
    cwd=self.cwd,
  File "/home/airflow/.local/lib/python3.7/site-packages/airflow/hooks/subprocess.py", line 87, in run_command
    for raw_line in iter(self.sub_process.stdout.readline, b''):
  File "/home/airflow/.local/lib/python3.7/site-packages/airflow/models/taskinstance.py", line 1410, in signal_handler
    raise AirflowException("Task received SIGTERM signal")
airflow.exceptions.AirflowException: Task received SIGTERM signal
[2022-02-01 07:39:21,821] {process_utils.py:70} INFO - Process psutil.Process(pid=189, status='terminated', exitcode=1, started='07:37:57') (189) terminated with exit code 1
[2022-02-01 07:39:21,823] {process_utils.py:70} INFO - Process psutil.Process(pid=190, status='terminated', started='07:37:57') (190) terminated with exit code None
[2022-02-01 07:39:21,825] {local_task_job.py:154} INFO - Task exited with return code 143
[2022-02-01 07:39:21,924] {local_task_job.py:264} INFO - 0 downstream tasks scheduled from follow-on schedule check
[2022-02-01 07:39:22,781] {local_task_job.py:82} ERROR - Received SIGTERM. Terminating subprocesses
[2022-02-01 07:39:22,783] {local_task_job.py:154} INFO - Task exited with return code 143
